Workbook

Sheet Cover
A1: TEST CASE DOCUMENT
A2: Fleet Management — <MODULE>
A4: Project Name | B4: Fleet Management | D4: Creator | E4: QA Team
A5: Module Name | B5: <MODULE> | D5: Create Date | E5: <DATE>
A6: Version | B6: <VER> | D6: Reviewer
A7: Source / Spec | B7: <SOURCE> | D7: Review Date
A9: RECORD OF CHANGE
A10: Effective Date | B10: Change Item | C10: Version | D10: *A, D, M | E10: Change Description | F10: Reference
A21: *A = Added · D = Deleted · M = Modified

Sheet Summary
A1: TEST RESULT SUMMARY
A2: <PROJECT> · <MODULE> · Version <VER> · All figures are live formulas over the "Test Cases" sheet.
A4: OVERALL
A5: Round | B5: Total | C5: Pass | D5: Fail | E5: Blocked | F5: Impact | G5: Not Run | H5: % Executed | I5: % Pass | J5: Status
A6: Round 1 | B6: =COUNTA('Test Cases'!$C$6:$C$33) | C6: =COUNTIF('Test Cases'!$J$6:$J$33,"Pass") | D6: =COUNTIF('Test Cases'!$J$6:$J$33,"Fail") | E6: =COUNTIF('Test Cases'!$J$6:$J$33,"Blocked") | F6: =COUNTIF('Test Cases'!$J$6:$J$33,"Impact") | G6: =$B6-$C6-$D6-$E6-$F6 | H6: =IFERROR(($B6-$G6)/$B6,0) | I6: =IFERROR($C6/($C6+$D6),0) | J6: =IF($G6=$B6,"Not started",IF($D6>0,"Needs attention",IF($G6>0,"In progress","Completed")))
A7: Round 2 | B7: =COUNTA('Test Cases'!$C$6:$C$33) | C7: =COUNTIF('Test Cases'!$L$6:$L$33,"Pass") | D7: =COUNTIF('Test Cases'!$L$6:$L$33,"Fail") | E7: =COUNTIF('Test Cases'!$L$6:$L$33,"Blocked") | F7: =COUNTIF('Test Cases'!$L$6:$L$33,"Impact") | G7: =$B7-$C7-$D7-$E7-$F7 | H7: =IFERROR(($B7-$G7)/$B7,0) | I7: =IFERROR($C7/($C7+$D7),0) | J7: =IF($G7=$B7,"Not started",IF($D7>0,"Needs attention",IF($G7>0,"In progress","Completed")))
A9: COVERAGE BY TYPE
A10: Type | B10: Total | C10: Pass | D10: Fail | E10: Blocked | F10: Impact | G10: Not Run | H10: % Executed | I10: % Pass | J10: Status
A11: UI | B11: =COUNTIF('Test Cases'!$C$6:$C$33,$A11) | C11: =COUNTIFS('Test Cases'!$C$6:$C$33,$A11,'Test Cases'!$J$6:$J$33,"Pass") | D11: =COUNTIFS('Test Cases'!$C$6:$C$33,$A11,'Test Cases'!$J$6:$J$33,"Fail") | E11: =COUNTIFS('Test Cases'!$C$6:$C$33,$A11,'Test Cases'!$J$6:$J$33,"Blocked") | F11: =COUNTIFS('Test Cases'!$C$6:$C$33,$A11,'Test Cases'!$J$6:$J$33,"Impact") | G11: =$B11-$C11-$D11-$E11-$F11 | H11: =IFERROR(($B11-$G11)/$B11,0) | I11: =IFERROR($C11/($C11+$D11),0) | J11: =IF($B11=0,"No case yet",IF($D11>0,"Needs attention",IF($G11=$B11,"Not started",IF($G11>0,"In progress","Completed"))))
A12: Validation | B12: =COUNTIF('Test Cases'!$C$6:$C$33,$A12) | C12: =COUNTIFS('Test Cases'!$C$6:$C$33,$A12,'Test Cases'!$J$6:$J$33,"Pass") | D12: =COUNTIFS('Test Cases'!$C$6:$C$33,$A12,'Test Cases'!$J$6:$J$33,"Fail") | E12: =COUNTIFS('Test Cases'!$C$6:$C$33,$A12,'Test Cases'!$J$6:$J$33,"Blocked") | F12: =COUNTIFS('Test Cases'!$C$6:$C$33,$A12,'Test Cases'!$J$6:$J$33,"Impact") | G12: =$B12-$C12-$D12-$E12-$F12 | H12: =IFERROR(($B12-$G12)/$B12,0) | I12: =IFERROR($C12/($C12+$D12),0) | J12: =IF($B12=0,"No case yet",IF($D12>0,"Needs attention",IF($G12=$B12,"Not started",IF($G12>0,"In progress","Completed"))))
A13: Boundary | B13: =COUNTIF('Test Cases'!$C$6:$C$33,$A13) | C13: =COUNTIFS('Test Cases'!$C$6:$C$33,$A13,'Test Cases'!$J$6:$J$33,"Pass") | D13: =COUNTIFS('Test Cases'!$C$6:$C$33,$A13,'Test Cases'!$J$6:$J$33,"Fail") | E13: =COUNTIFS('Test Cases'!$C$6:$C$33,$A13,'Test Cases'!$J$6:$J$33,"Blocked") | F13: =COUNTIFS('Test Cases'!$C$6:$C$33,$A13,'Test Cases'!$J$6:$J$33,"Impact") | G13: =$B13-$C13-$D13-$E13-$F13 | H13: =IFERROR(($B13-$G13)/$B13,0) | I13: =IFERROR($C13/($C13+$D13),0) | J13: =IF($B13=0,"No case yet",IF($D13>0,"Needs attention",IF($G13=$B13,"Not started",IF($G13>0,"In progress","Completed"))))
A14: Negative | B14: =COUNTIF('Test Cases'!$C$6:$C$33,$A14) | C14: =COUNTIFS('Test Cases'!$C$6:$C$33,$A14,'Test Cases'!$J$6:$J$33,"Pass") | D14: =COUNTIFS('Test Cases'!$C$6:$C$33,$A14,'Test Cases'!$J$6:$J$33,"Fail") | E14: =COUNTIFS('Test Cases'!$C$6:$C$33,$A14,'Test Cases'!$J$6:$J$33,"Blocked") | F14: =COUNTIFS('Test Cases'!$C$6:$C$33,$A14,'Test Cases'!$J$6:$J$33,"Impact") | G14: =$B14-$C14-$D14-$E14-$F14 | H14: =IFERROR(($B14-$G14)/$B14,0) | I14: =IFERROR($C14/($C14+$D14),0) | J14: =IF($B14=0,"No case yet",IF($D14>0,"Needs attention",IF($G14=$B14,"Not started",IF($G14>0,"In progress","Completed"))))
A15: Functional | B15: =COUNTIF('Test Cases'!$C$6:$C$33,$A15) | C15: =COUNTIFS('Test Cases'!$C$6:$C$33,$A15,'Test Cases'!$J$6:$J$33,"Pass") | D15: =COUNTIFS('Test Cases'!$C$6:$C$33,$A15,'Test Cases'!$J$6:$J$33,"Fail") | E15: =COUNTIFS('Test Cases'!$C$6:$C$33,$A15,'Test Cases'!$J$6:$J$33,"Blocked") | F15: =COUNTIFS('Test Cases'!$C$6:$C$33,$A15,'Test Cases'!$J$6:$J$33,"Impact") | G15: =$B15-$C15-$D15-$E15-$F15 | H15: =IFERROR(($B15-$G15)/$B15,0) | I15: =IFERROR($C15/($C15+$D15),0) | J15: =IF($B15=0,"No case yet",IF($D15>0,"Needs attention",IF($G15=$B15,"Not started",IF($G15>0,"In progress","Completed"))))
A16: Business rule | B16: =COUNTIF('Test Cases'!$C$6:$C$33,$A16) | C16: =COUNTIFS('Test Cases'!$C$6:$C$33,$A16,'Test Cases'!$J$6:$J$33,"Pass") | D16: =COUNTIFS('Test Cases'!$C$6:$C$33,$A16,'Test Cases'!$J$6:$J$33,"Fail") | E16: =COUNTIFS('Test Cases'!$C$6:$C$33,$A16,'Test Cases'!$J$6:$J$33,"Blocked") | F16: =COUNTIFS('Test Cases'!$C$6:$C$33,$A16,'Test Cases'!$J$6:$J$33,"Impact") | G16: =$B16-$C16-$D16-$E16-$F16 | H16: =IFERROR(($B16-$G16)/$B16,0) | I16: =IFERROR($C16/($C16+$D16),0) | J16: =IF($B16=0,"No case yet",IF($D16>0,"Needs attention",IF($G16=$B16,"Not started",IF($G16>0,"In progress","Completed"))))
A17: API | B17: =COUNTIF('Test Cases'!$C$6:$C$33,$A17) | C17: =COUNTIFS('Test Cases'!$C$6:$C$33,$A17,'Test Cases'!$J$6:$J$33,"Pass") | D17: =COUNTIFS('Test Cases'!$C$6:$C$33,$A17,'Test Cases'!$J$6:$J$33,"Fail") | E17: =COUNTIFS('Test Cases'!$C$6:$C$33,$A17,'Test Cases'!$J$6:$J$33,"Blocked") | F17: =COUNTIFS('Test Cases'!$C$6:$C$33,$A17,'Test Cases'!$J$6:$J$33,"Impact") | G17: =$B17-$C17-$D17-$E17-$F17 | H17: =IFERROR(($B17-$G17)/$B17,0) | I17: =IFERROR($C17/($C17+$D17),0) | J17: =IF($B17=0,"No case yet",IF($D17>0,"Needs attention",IF($G17=$B17,"Not started",IF($G17>0,"In progress","Completed"))))
A19: RESULT BY SECTION
A20: Section | B20: Total | C20: Pass | D20: Fail | E20: Blocked | F20: Impact | G20: Not Run | H20: % Executed | I20: % Pass | J20: Status
B21: =COUNTIF('Test Cases'!$B$6:$B$33,$A21) | C21: =COUNTIFS('Test Cases'!$B$6:$B$33,$A21,'Test Cases'!$J$6:$J$33,"Pass") | D21: =COUNTIFS('Test Cases'!$B$6:$B$33,$A21,'Test Cases'!$J$6:$J$33,"Fail") | E21: =COUNTIFS('Test Cases'!$B$6:$B$33,$A21,'Test Cases'!$J$6:$J$33,"Blocked") | F21: =COUNTIFS('Test Cases'!$B$6:$B$33,$A21,'Test Cases'!$J$6:$J$33,"Impact") | G21: =$B21-$C21-$D21-$E21-$F21 | H21: =IFERROR(($B21-$G21)/$B21,0) | I21: =IFERROR($C21/($C21+$D21),0) | J21: =IF($B21=0,"No case yet",IF($D21>0,"Needs attention",IF($G21=$B21,"Not started",IF($G21>0,"In progress","Completed"))))
B22: =COUNTIF('Test Cases'!$B$6:$B$33,$A22) | C22: =COUNTIFS('Test Cases'!$B$6:$B$33,$A22,'Test Cases'!$J$6:$J$33,"Pass") | D22: =COUNTIFS('Test Cases'!$B$6:$B$33,$A22,'Test Cases'!$J$6:$J$33,"Fail") | E22: =COUNTIFS('Test Cases'!$B$6:$B$33,$A22,'Test Cases'!$J$6:$J$33,"Blocked") | F22: =COUNTIFS('Test Cases'!$B$6:$B$33,$A22,'Test Cases'!$J$6:$J$33,"Impact") | G22: =$B22-$C22-$D22-$E22-$F22 | H22: =IFERROR(($B22-$G22)/$B22,0) | I22: =IFERROR($C22/($C22+$D22),0) | J22: =IF($B22=0,"No case yet",IF($D22>0,"Needs attention",IF($G22=$B22,"Not started",IF($G22>0,"In progress","Completed"))))
B23: =COUNTIF('Test Cases'!$B$6:$B$33,$A23) | C23: =COUNTIFS('Test Cases'!$B$6:$B$33,$A23,'Test Cases'!$J$6:$J$33,"Pass") | D23: =COUNTIFS('Test Cases'!$B$6:$B$33,$A23,'Test Cases'!$J$6:$J$33,"Fail") | E23: =COUNTIFS('Test Cases'!$B$6:$B$33,$A23,'Test Cases'!$J$6:$J$33,"Blocked") | F23: =COUNTIFS('Test Cases'!$B$6:$B$33,$A23,'Test Cases'!$J$6:$J$33,"Impact") | G23: =$B23-$C23-$D23-$E23-$F23 | H23: =IFERROR(($B23-$G23)/$B23,0) | I23: =IFERROR($C23/($C23+$D23),0) | J23: =IF($B23=0,"No case yet",IF($D23>0,"Needs attention",IF($G23=$B23,"Not started",IF($G23>0,"In progress","Completed"))))
B24: =COUNTIF('Test Cases'!$B$6:$B$33,$A24) | C24: =COUNTIFS('Test Cases'!$B$6:$B$33,$A24,'Test Cases'!$J$6:$J$33,"Pass") | D24: =COUNTIFS('Test Cases'!$B$6:$B$33,$A24,'Test Cases'!$J$6:$J$33,"Fail") | E24: =COUNTIFS('Test Cases'!$B$6:$B$33,$A24,'Test Cases'!$J$6:$J$33,"Blocked") | F24: =COUNTIFS('Test Cases'!$B$6:$B$33,$A24,'Test Cases'!$J$6:$J$33,"Impact") | G24: =$B24-$C24-$D24-$E24-$F24 | H24: =IFERROR(($B24-$G24)/$B24,0) | I24: =IFERROR($C24/($C24+$D24),0) | J24: =IF($B24=0,"No case yet",IF($D24>0,"Needs attention",IF($G24=$B24,"Not started",IF($G24>0,"In progress","Completed"))))
B25: =COUNTIF('Test Cases'!$B$6:$B$33,$A25) | C25: =COUNTIFS('Test Cases'!$B$6:$B$33,$A25,'Test Cases'!$J$6:$J$33,"Pass") | D25: =COUNTIFS('Test Cases'!$B$6:$B$33,$A25,'Test Cases'!$J$6:$J$33,"Fail") | E25: =COUNTIFS('Test Cases'!$B$6:$B$33,$A25,'Test Cases'!$J$6:$J$33,"Blocked") | F25: =COUNTIFS('Test Cases'!$B$6:$B$33,$A25,'Test Cases'!$J$6:$J$33,"Impact") | G25: =$B25-$C25-$D25-$E25-$F25 | H25: =IFERROR(($B25-$G25)/$B25,0) | I25: =IFERROR($C25/($C25+$D25),0) | J25: =IF($B25=0,"No case yet",IF($D25>0,"Needs attention",IF($G25=$B25,"Not started",IF($G25>0,"In progress","Completed"))))
B26: =COUNTIF('Test Cases'!$B$6:$B$33,$A26) | C26: =COUNTIFS('Test Cases'!$B$6:$B$33,$A26,'Test Cases'!$J$6:$J$33,"Pass") | D26: =COUNTIFS('Test Cases'!$B$6:$B$33,$A26,'Test Cases'!$J$6:$J$33,"Fail") | E26: =COUNTIFS('Test Cases'!$B$6:$B$33,$A26,'Test Cases'!$J$6:$J$33,"Blocked") | F26: =COUNTIFS('Test Cases'!$B$6:$B$33,$A26,'Test Cases'!$J$6:$J$33,"Impact") | G26: =$B26-$C26-$D26-$E26-$F26 | H26: =IFERROR(($B26-$G26)/$B26,0) | I26: =IFERROR($C26/($C26+$D26),0) | J26: =IF($B26=0,"No case yet",IF($D26>0,"Needs attention",IF($G26=$B26,"Not started",IF($G26>0,"In progress","Completed"))))
B27: =COUNTIF('Test Cases'!$B$6:$B$33,$A27) | C27: =COUNTIFS('Test Cases'!$B$6:$B$33,$A27,'Test Cases'!$J$6:$J$33,"Pass") | D27: =COUNTIFS('Test Cases'!$B$6:$B$33,$A27,'Test Cases'!$J$6:$J$33,"Fail") | E27: =COUNTIFS('Test Cases'!$B$6:$B$33,$A27,'Test Cases'!$J$6:$J$33,"Blocked") | F27: =COUNTIFS('Test Cases'!$B$6:$B$33,$A27,'Test Cases'!$J$6:$J$33,"Impact") | G27: =$B27-$C27-$D27-$E27-$F27 | H27: =IFERROR(($B27-$G27)/$B27,0) | I27: =IFERROR($C27/($C27+$D27),0) | J27: =IF($B27=0,"No case yet",IF($D27>0,"Needs attention",IF($G27=$B27,"Not started",IF($G27>0,"In progress","Completed"))))
B28: =COUNTIF('Test Cases'!$B$6:$B$33,$A28) | C28: =COUNTIFS('Test Cases'!$B$6:$B$33,$A28,'Test Cases'!$J$6:$J$33,"Pass") | D28: =COUNTIFS('Test Cases'!$B$6:$B$33,$A28,'Test Cases'!$J$6:$J$33,"Fail") | E28: =COUNTIFS('Test Cases'!$B$6:$B$33,$A28,'Test Cases'!$J$6:$J$33,"Blocked") | F28: =COUNTIFS('Test Cases'!$B$6:$B$33,$A28,'Test Cases'!$J$6:$J$33,"Impact") | G28: =$B28-$C28-$D28-$E28-$F28 | H28: =IFERROR(($B28-$G28)/$B28,0) | I28: =IFERROR($C28/($C28+$D28),0) | J28: =IF($B28=0,"No case yet",IF($D28>0,"Needs attention",IF($G28=$B28,"Not started",IF($G28>0,"In progress","Completed"))))
B29: =COUNTIF('Test Cases'!$B$6:$B$33,$A29) | C29: =COUNTIFS('Test Cases'!$B$6:$B$33,$A29,'Test Cases'!$J$6:$J$33,"Pass") | D29: =COUNTIFS('Test Cases'!$B$6:$B$33,$A29,'Test Cases'!$J$6:$J$33,"Fail") | E29: =COUNTIFS('Test Cases'!$B$6:$B$33,$A29,'Test Cases'!$J$6:$J$33,"Blocked") | F29: =COUNTIFS('Test Cases'!$B$6:$B$33,$A29,'Test Cases'!$J$6:$J$33,"Impact") | G29: =$B29-$C29-$D29-$E29-$F29 | H29: =IFERROR(($B29-$G29)/$B29,0) | I29: =IFERROR($C29/($C29+$D29),0) | J29: =IF($B29=0,"No case yet",IF($D29>0,"Needs attention",IF($G29=$B29,"Not started",IF($G29>0,"In progress","Completed"))))
B30: =COUNTIF('Test Cases'!$B$6:$B$33,$A30) | C30: =COUNTIFS('Test Cases'!$B$6:$B$33,$A30,'Test Cases'!$J$6:$J$33,"Pass") | D30: =COUNTIFS('Test Cases'!$B$6:$B$33,$A30,'Test Cases'!$J$6:$J$33,"Fail") | E30: =COUNTIFS('Test Cases'!$B$6:$B$33,$A30,'Test Cases'!$J$6:$J$33,"Blocked") | F30: =COUNTIFS('Test Cases'!$B$6:$B$33,$A30,'Test Cases'!$J$6:$J$33,"Impact") | G30: =$B30-$C30-$D30-$E30-$F30 | H30: =IFERROR(($B30-$G30)/$B30,0) | I30: =IFERROR($C30/($C30+$D30),0) | J30: =IF($B30=0,"No case yet",IF($D30>0,"Needs attention",IF($G30=$B30,"Not started",IF($G30>0,"In progress","Completed"))))
B31: =COUNTIF('Test Cases'!$B$6:$B$33,$A31) | C31: =COUNTIFS('Test Cases'!$B$6:$B$33,$A31,'Test Cases'!$J$6:$J$33,"Pass") | D31: =COUNTIFS('Test Cases'!$B$6:$B$33,$A31,'Test Cases'!$J$6:$J$33,"Fail") | E31: =COUNTIFS('Test Cases'!$B$6:$B$33,$A31,'Test Cases'!$J$6:$J$33,"Blocked") | F31: =COUNTIFS('Test Cases'!$B$6:$B$33,$A31,'Test Cases'!$J$6:$J$33,"Impact") | G31: =$B31-$C31-$D31-$E31-$F31 | H31: =IFERROR(($B31-$G31)/$B31,0) | I31: =IFERROR($C31/($C31+$D31),0) | J31: =IF($B31=0,"No case yet",IF($D31>0,"Needs attention",IF($G31=$B31,"Not started",IF($G31>0,"In progress","Completed"))))
B32: =COUNTIF('Test Cases'!$B$6:$B$33,$A32) | C32: =COUNTIFS('Test Cases'!$B$6:$B$33,$A32,'Test Cases'!$J$6:$J$33,"Pass") | D32: =COUNTIFS('Test Cases'!$B$6:$B$33,$A32,'Test Cases'!$J$6:$J$33,"Fail") | E32: =COUNTIFS('Test Cases'!$B$6:$B$33,$A32,'Test Cases'!$J$6:$J$33,"Blocked") | F32: =COUNTIFS('Test Cases'!$B$6:$B$33,$A32,'Test Cases'!$J$6:$J$33,"Impact") | G32: =$B32-$C32-$D32-$E32-$F32 | H32: =IFERROR(($B32-$G32)/$B32,0) | I32: =IFERROR($C32/($C32+$D32),0) | J32: =IF($B32=0,"No case yet",IF($D32>0,"Needs attention",IF($G32=$B32,"Not started",IF($G32>0,"In progress","Completed"))))
A34: RESULT BY PRIORITY
A35: Priority | B35: Total | C35: Pass | D35: Fail | E35: Blocked | F35: Impact | G35: Not Run | H35: % Executed | I35: % Pass | J35: Status
A36: High | B36: =COUNTIF('Test Cases'!$D$6:$D$33,$A36) | C36: =COUNTIFS('Test Cases'!$D$6:$D$33,$A36,'Test Cases'!$J$6:$J$33,"Pass") | D36: =COUNTIFS('Test Cases'!$D$6:$D$33,$A36,'Test Cases'!$J$6:$J$33,"Fail") | E36: =COUNTIFS('Test Cases'!$D$6:$D$33,$A36,'Test Cases'!$J$6:$J$33,"Blocked") | F36: =COUNTIFS('Test Cases'!$D$6:$D$33,$A36,'Test Cases'!$J$6:$J$33,"Impact") | G36: =$B36-$C36-$D36-$E36-$F36 | H36: =IFERROR(($B36-$G36)/$B36,0) | I36: =IFERROR($C36/($C36+$D36),0) | J36: =IF($B36=0,"No case yet",IF($D36>0,"Needs attention",IF($G36=$B36,"Not started",IF($G36>0,"In progress","Completed"))))
A37: Medium | B37: =COUNTIF('Test Cases'!$D$6:$D$33,$A37) | C37: =COUNTIFS('Test Cases'!$D$6:$D$33,$A37,'Test Cases'!$J$6:$J$33,"Pass") | D37: =COUNTIFS('Test Cases'!$D$6:$D$33,$A37,'Test Cases'!$J$6:$J$33,"Fail") | E37: =COUNTIFS('Test Cases'!$D$6:$D$33,$A37,'Test Cases'!$J$6:$J$33,"Blocked") | F37: =COUNTIFS('Test Cases'!$D$6:$D$33,$A37,'Test Cases'!$J$6:$J$33,"Impact") | G37: =$B37-$C37-$D37-$E37-$F37 | H37: =IFERROR(($B37-$G37)/$B37,0) | I37: =IFERROR($C37/($C37+$D37),0) | J37: =IF($B37=0,"No case yet",IF($D37>0,"Needs attention",IF($G37=$B37,"Not started",IF($G37>0,"In progress","Completed"))))
A38: Low | B38: =COUNTIF('Test Cases'!$D$6:$D$33,$A38) | C38: =COUNTIFS('Test Cases'!$D$6:$D$33,$A38,'Test Cases'!$J$6:$J$33,"Pass") | D38: =COUNTIFS('Test Cases'!$D$6:$D$33,$A38,'Test Cases'!$J$6:$J$33,"Fail") | E38: =COUNTIFS('Test Cases'!$D$6:$D$33,$A38,'Test Cases'!$J$6:$J$33,"Blocked") | F38: =COUNTIFS('Test Cases'!$D$6:$D$33,$A38,'Test Cases'!$J$6:$J$33,"Impact") | G38: =$B38-$C38-$D38-$E38-$F38 | H38: =IFERROR(($B38-$G38)/$B38,0) | I38: =IFERROR($C38/($C38+$D38),0) | J38: =IF($B38=0,"No case yet",IF($D38>0,"Needs attention",IF($G38=$B38,"Not started",IF($G38>0,"In progress","Completed"))))
A40: LEGEND — status colours used on the Test Cases sheets
A41: Pass | B41: Actual result matches the Expected Result.
A42: Fail | B42: Actual result differs from the Expected Result. A Bug ID and a row in Defects & Follow-ups are required.
A43: Blocked | B43: Cannot be executed automatically yet — dependency unresolved (build, test data, env) OR the case must be run manually. Manual cases MUST have Note starting with [MANUAL].
A44: Impact | B44: Not re-executed but affected by a change elsewhere. Needs assessment.
A45: Not Run | B45: Not executed yet.
...

Sheet Test Cases
A1: <MODULE> — Test Cases
A2: Source: <SOURCE> · Version <VER> · <DATE>
A4: ID | B4: Section | C4: Type | D4: Priority | E4: Test Case Title | F4: Precondition | G4: Test Steps | H4: Test Data | I4: Expected Result | J4: Round 1 | L4: Round 2 | N4: Note / Ref
J5: Result | K5: Bug ID | L5: Result | M5: Bug ID

Sheet Test Cases_VN
A1: <MODULE> — Test Cases (Vietnamese reference)
A2: REFERENCE ONLY — mọi số liệu ở sheet Summary được tính từ sheet "Test Cases" (EN). · Source: <SOURCE> · Version <VER> · <DATE>
A4: ID | B4: Section | C4: Type | D4: Priority | E4: Test Case Title | F4: Precondition | G4: Test Steps | H4: Test Data | I4: Expected Result | J4: Round 1 | L4: Round 2 | N4: Note / Ref
J5: Result | K5: Bug ID | L5: Result | M5: Bug ID

Sheet Common Validate
A1: COMMON VALIDATE — reusable checklist for every screen
A2: Use this sheet as the source. For each field on the screen, open the matching group, mark "Applicable?", then turn each applicable line into a concrete test case on the "Test Cases" sheet using the real field name, real data and the real message.
A3: # | B3: Check Item | C3: Suggested Test Data | D3: Expected Output | E3: Applicable?
A4: Text field (maxlength 255)
A5: 1 | B5: Default state | D5: Correct label, placeholder, default value, required marker (*), enabled/disabled state.
A6: 2 | B6: Valid input | C6: A valid string per the requirement | D6: Saved successfully; the value is shown correctly on both the list and the detail screen.
A7: 3 | B7: Empty / spaces only | C7: " " (spaces) | D7: Required-field error is displayed, focus moves to the field, the API is not called.
A8: 4 | B8: Below maxlength | C8: 254 characters | D8: Accepted and saved successfully.
A9: 5 | B9: Exactly maxlength | C9: 255 characters | D9: Accepted and saved successfully.
A10: 6 | B10: Over maxlength | C10: 256 characters | D10: Input is capped at the limit, or a maximum-length error is displayed.
A11: 7 | B11: Leading and trailing spaces | C11: " abc " | D11: Spaces are trimmed on save per the requirement and are not counted towards maxlength.
A12: 8 | B12: Special characters | C12: ~`!#$%^&*()_-+={}[]|\:;"'<,>?/.@ | D12: No system error; the value is displayed back exactly as entered.
A13: 9 | B13: HTML and script tags | C13: <b>test</b> · <script>alert(1)</script> | D13: Escaped and rendered as plain text; the script is not executed.
A14: 10 | B14: Multi-byte characters and emoji | C14: Tiếng Việt · 日本語 · 😀 | D14: Stored and displayed correctly, no missing or corrupted characters.
A15: 11 | B15: Paste content over the limit | C15: Paste 300 characters | D15: Only maxlength is accepted, or an error is shown; the UI does not freeze.
A16: 12 | B16: Line break characters | C16: Enter key · </br> | D16: Per the requirement: either blocked, or stored and rendered correctly.
A17: Email
A18: 13 | B18: Valid format | C18: abc@test.com · a.b+c@sub.test.co.jp | D18: Saved successfully.
A19: 14 | B19: Invalid format | C19: abc · abc@ · @test.com · abc@.com · abc @test.com | D19: Email format error is displayed, focus moves to the field.
A20: 15 | B20: Full-width / half-width characters | C20: ａｂｃ@gmail.com · ｱｲｳ@gmail.com | D20: Email format error is displayed.
A21: 16 | B21: Over maxlength | C21: More than 128 characters | D21: Input is capped at the limit, or an error is displayed.
A22: 17 | B22: Duplicate email | C22: An email already registered in the system | D22: Duplicate error is displayed; no new record is created.
A23: 18 | B23: Case sensitivity | C23: ABC@test.com vs abc@test.com | D23: Per the requirement; usually treated as the same address.
A24: Password
A25: 19 | B25: Meets the password policy | C25: Test@1234 | D25: Saved successfully.
A26: 20 | B26: Missing a required character class | C26: test1234 (no uppercase, no symbol) | D26: Error message states the password requirements.
A27: 21 | B27: Below / equal / above the minimum length | C27: 7 · 8 · 9 characters | D27: 7 fails; 8 and 9 are accepted.
A28: 22 | B28: Toggle password visibility | D28: The eye icon reveals and re-masks the value correctly.
A29: 23 | B29: Confirm password mismatch | C29: Test@1234 vs Test@12345 | D29: Mismatch error is displayed.
A30: 24 | B30: Paste blocked (if required) | C30: Ctrl+V | D30: Per the requirement.
A31: 25 | B31: Not logged or exposed in plain text | D31: Not present in clear text in the network request or in application logs.
A32: Number / Amount
A33: 26 | B33: Valid number | C33: 100 | D33: Saved successfully.
A34: 27 | B34: Letters in a numeric field | C34: abc | D34: Input is rejected, or an error is displayed.
A35: 28 | B35: Negative number | C35: -1 | D35: Per the requirement: blocked or accepted.
A36: 29 | B36: Zero | C36: 0 | D36: Per the requirement.
A37: 30 | B37: Min and max boundaries ±1 | C37: min-1 · min · max · max+1 | D37: min-1 and max+1 fail; min and max are accepted.
A38: 31 | B38: Decimals and rounding | C38: 1.005 · 1.994 | D38: Rounded per the rule, with the correct number of decimal places.
A39: 32 | B39: Thousand separator | C39: 1234567 | D39: Displayed as 1,234,567 in the correct format.
A40: 33 | B40: Very large number | C40: 99999999999999999999 | D40: No overflow and no system error.
...

Sheet Defects & Follow-ups
A1: DEFECTS & FOLLOW-UPS
A2: Add one row for every test case whose result is Fail or Blocked, and for every point that still needs a decision from BA or Dev.
A3: # | B3: TC ID | C3: Section | D3: Test Case Title | E3: Description | F3: Round | G3: Priority | H3: Actual Result / Reason | I3: Bug ID / Ticket | J3: Assignee | K3: Fix Status

Sheet Traceability
A1: TRACEABILITY — Acceptance Criteria → Test Cases
A2: Mỗi AC trong checklist phải có ít nhất một test case. Dòng có Coverage = MISSING là AC chưa được phủ — phải xử lý trước khi giao bộ test case.
A3: AC ID | B3: Nội dung / ghi chú | C3: Test Case IDs | D3: Số TC | E3: Coverage

Sheet Assumptions & Questions
A1: ASSUMPTIONS & QUESTIONS
A2: Every expected result that cannot be derived directly from the spec needs a row here. The related test case references this number in its Note column.
A3: # | B3: Topic | C3: Gap in the spec | D3: Working assumption | E3: Question for BA / Dev | F3: Answer | G3: Date closed
